Workbook

Sheet Business Details
A1: Business Details
A2: Firm Name: | B2: DYP INFRAPROJECTS PRIVATE LIMITED
A3: GST NO. | B3: 27AAGCD4105L1ZO
A4: GSTN Status: | B4: Active
A5: Registration Date:
A6: Address:
A7: Contact Person:
A8: Financial Year: | B8: 2026-27
A9: Nature Of Business:
A10: Authorised Signatory:
A11: Filing Type: | B11: Digital Signature
A12: Filing Email ID:
A13: Filing Mobile No.

Sheet April-2026
G1: April
B2: DYP INFRAPROJECTS PRIVATE LIMITED
B3: GST No. 27AAGCD4105L1ZO
B5: GSTR-3B WORKING FOR THE MONTH OF APRIL 2026
B6: PARTICULARS | D6: TAXABLE | E6: CGST | F6: SGST | G6: IGST | H6: TOTAL
B8: Outward Supply | C8: Sales (B2B) | D8: 0 | E8: 0 | F8: 0 | G8: 0 | H8: =SUM(E8:G8) -> 0
C9: Sales (B2C) | D9: 0 | E9: 0 | F9: 0 | G9: 0 | H9: =SUM(E9:G9) -> 0
C10: SEZ supply with payment | D10: 0 | E10: 0 | F10: 0 | G10: 0 | H10: =SUM(E10:G10) -> 0
C11: SEZ supply without-payment | D11: 0 | E11: 0 | F11: 0 | G11: 0 | H11: =SUM(E11:G11) -> 0
C12: Zero Rated Supply/Export Sale | D12: 0 | E12: 0 | F12: 0 | G12: 0 | H12: =SUM(E12:G12) -> 0
C13: Nil Rated Supply | D13: 0 | E13: 0 | F13: 0 | G13: 0 | H13: =SUM(E13:G13) -> 0
C14: Exempt Sale | D14: 0 | E14: 0 | F14: 0 | G14: 0 | H14: =SUM(E14:G14) -> 0
C15: Advances Collected for Services | D15: 0 | E15: 0 | F15: 0 | G15: 0 | H15: =SUM(E15:G15) -> 0
C16: Rent Received | D16: 0 | E16: 0 | F16: 0 | G16: 0 | H16: =SUM(E16:G16) -> 0
C17: Sale Increased through Amendment | D17: 0 | E17: 0 | F17: 0 | G17: 0 | H17: =SUM(E17:G17) -> 0
C18: (-) Sale Decreased through Amendment | D18: 0 | E18: 0 | F18: 0 | G18: 0 | H18: =SUM(E18:G18) -> 0
C19: (-) Credit Note | D19: 0 | E19: 0 | F19: 0 | G19: 0 | H19: =SUM(E19:G19) -> 0
C20: (-) Advances Settled Against Services | D20: 0 | E20: 0 | F20: 0 | G20: 0 | H20: =SUM(E20:G20) -> 0
C22: Total Sale as per Working | D22: =SUM(D8:D17)-SUM(D18:D20) -> 0 | E22: =SUM(E8:E17)-SUM(E18:E20) -> 0 | F22: =SUM(F8:F17)-SUM(F18:F20) -> 0 | G22: =SUM(G8:G17)-SUM(G18:G20) -> 0 | H22: =SUM(H8:H17)-SUM(H18:H20) -> 0
C24: Reverse Charge on Inward Supplies | D24: =SUM(D25:D28) -> 0 | E24: =SUM(E25:E28) -> 0 | F24: =SUM(F25:F28) -> 0 | G24: =SUM(G25:G28) -> 0 | H24: =SUM(H25:H28) -> 0
C25: RCM on Transport Charges 5% | D25: 0 | E25: 0 | F25: 0 | G25: 0 | H25: =SUM(E25:G25) -> 0
C26: RCM on Security Charges 18% | D26: 0 | E26: 0 | F26: 0 | G26: 0 | H26: =SUM(E26:G26) -> 0
C27: RCM on Guest House Charges 18% | D27: 0 | E27: 0 | F27: 0 | G27: 0 | H27: =SUM(E27:G27) -> 0
C28: RCM on Advocate Charges 18% | D28: 0 | E28: 0 | F28: 0 | G28: 0 | H28: =SUM(E28:G28) -> 0
C30: (A) Total Sale as per Working including Reverse Charge | D30: =SUM(D22:D24) -> 0 | E30: =SUM(E22:E24) -> 0 | F30: =SUM(F22:F24) -> 0 | G30: =SUM(G22:G24) -> 0 | H30: =SUM(H22:H24) -> 0
B31: Inward Supplies
C32: ITC (As per books) | H32: 0
C33: ITC as per GSTR 2B | D33: 0 | E33: 0 | F33: 0 | G33: 0 | H33: =SUM(E33:G33) -> 0
C34: (+) Import purchase | D34: 0 | E34: 0 | F34: 0 | G34: 0 | H34: =SUM(E34:G34) -> 0
C35: (+) RCM paid on Inward Supplies | D35: =D24 -> 0 | E35: =E24 -> 0 | F35: =F24 -> 0 | G35: =G24 -> 0 | H35: =SUM(E35:G35) -> 0
C36: (+) Credit Notes | D36: 0 | E36: 0 | F36: 0 | G36: 0 | H36: =SUM(E36:G36) -> 0
C37: (+) Opening Credit Balance | D37: 0 | E37: 0 | F37: 0 | G37: 0 | H37: =SUM(E37:G37) -> 0
C38: (-) Debit Notes | D38: 0 | E38: 0 | F38: 0 | G38: 0 | H38: =SUM(E38:G38) -> 0
C39: (-) ITC Reversed on Ineligible credit | D39: 0 | E39: 0 | F39: 0 | G39: 0 | H39: =SUM(E39:G39) -> 0
C41: (B) Total ITC Available for Set off | D41: =SUM(D33:D37)-SUM(D38:D39) -> 0 | E41: =SUM(E33:E37)-SUM(E38:E39) -> 0 | F41: =SUM(F33:F37)-SUM(F38:F39) -> 0 | G41: =SUM(G33:G37)-SUM(G38:G39) -> 0 | H41: =SUM(H33:H37)-SUM(H38:H39) -> 0
B43: Tax Set-off | C43: (A-B) Payable | E43: =E22-E41 -> 0 | F43: =F22-F41 -> 0 | G43: =G22-G41 -> 0 | H43: =H22-H41 -> 0
C44: (-) Adjustment | E44: 0 | F44: 0 | G44: 0 | H44: =SUM(E44:G44) -> 0
C46: (-) GST TDS/TCS Opening Cash Balance | E46: 0 | F46: 0 | G46: 0 | H46: =SUM(D46:G46) -> 0
C48: Final Liability Payable | E48: =IF(E43-E44>0,E43-E44,0)-E46 -> 0 | F48: =IF(F43-F44>0,F43-F44,0)-F46 -> 0 | G48: =IF(G43-G44>0,G43-G44,0)-G46 -> 0 | H48: =IF(H43-H44>0,H43-H44,0)-H46 -> 0
C50: Balance C/f to next month | E50: =IF(E43-E44<0,E44-E43,0) -> 0 | F50: =IF(F43-F44<0,F44-F43,0) -> 0 | G50: =IF(G43-G44<0,G44-G43,0) -> 0 | H50: =SUM(E50:G50) -> 0
...

Sheet May-2026
G1: May
B2: DYP INFRAPROJECTS PRIVATE LIMITED
B3: GST No. 27AAGCD4105L1ZO
B5: GSTR-3B WORKING FOR THE MONTH OF MAY 2026
B6: PARTICULARS | D6: TAXABLE | E6: CGST | F6: SGST | G6: IGST | H6: TOTAL
B8: Outward Supply | C8: Sales (B2B) | D8: 0 | E8: 0 | F8: 0 | G8: 0 | H8: =SUM(E8:G8) -> 0
C9: Sales (B2C) | D9: 0 | E9: 0 | F9: 0 | G9: 0 | H9: =SUM(E9:G9) -> 0
C10: SEZ supply with payment | D10: 0 | E10: 0 | F10: 0 | G10: 0 | H10: =SUM(E10:G10) -> 0
C11: SEZ supply without-payment | D11: 0 | E11: 0 | F11: 0 | G11: 0 | H11: =SUM(E11:G11) -> 0
C12: Zero Rated Supply/Export Sale | D12: 0 | E12: 0 | F12: 0 | G12: 0 | H12: =SUM(E12:G12) -> 0
C13: Nil Rated Supply | D13: 0 | E13: 0 | F13: 0 | G13: 0 | H13: =SUM(E13:G13) -> 0
C14: Exempt Sale | D14: 0 | E14: 0 | F14: 0 | G14: 0 | H14: =SUM(E14:G14) -> 0
C15: Advances Collected for Services | D15: 0 | E15: 0 | F15: 0 | G15: 0 | H15: =SUM(E15:G15) -> 0
C16: Rent Received | D16: 0 | E16: 0 | F16: 0 | G16: 0 | H16: =SUM(E16:G16) -> 0
C17: Sale Increased through Amendment | D17: 0 | E17: 0 | F17: 0 | G17: 0 | H17: =SUM(E17:G17) -> 0
C18: (-) Sale Decreased through Amendment | D18: 0 | E18: 0 | F18: 0 | G18: 0 | H18: =SUM(E18:G18) -> 0
C19: (-) Credit Note | D19: 0 | E19: 0 | F19: 0 | G19: 0 | H19: =SUM(E19:G19) -> 0
C20: (-) Advances Settled Against Services | D20: 0 | E20: 0 | F20: 0 | G20: 0 | H20: =SUM(E20:G20) -> 0
C22: Total Sale as per Working | D22: =SUM(D8:D17)-SUM(D18:D20) -> 0 | E22: =SUM(E8:E17)-SUM(E18:E20) -> 0 | F22: =SUM(F8:F17)-SUM(F18:F20) -> 0 | G22: =SUM(G8:G17)-SUM(G18:G20) -> 0 | H22: =SUM(H8:H17)-SUM(H18:H20) -> 0
C24: Reverse Charge on Inward Supplies | D24: =SUM(D25:D28) -> 0 | E24: =SUM(E25:E28) -> 0 | F24: =SUM(F25:F28) -> 0 | G24: =SUM(G25:G28) -> 0 | H24: =SUM(H25:H28) -> 0
C25: RCM on Transport Charges 5% | D25: 0 | E25: 0 | F25: 0 | G25: 0 | H25: =SUM(E25:G25) -> 0
C26: RCM on Security Charges 18% | D26: 0 | E26: 0 | F26: 0 | G26: 0 | H26: =SUM(E26:G26) -> 0
C27: RCM on Guest House Charges 18% | D27: 0 | E27: 0 | F27: 0 | G27: 0 | H27: =SUM(E27:G27) -> 0
C28: RCM on Advocate Charges 18% | D28: 0 | E28: 0 | F28: 0 | G28: 0 | H28: =SUM(E28:G28) -> 0
C30: (A) Total Sale as per Working including Reverse Charge | D30: =SUM(D22:D24) -> 0 | E30: =SUM(E22:E24) -> 0 | F30: =SUM(F22:F24) -> 0 | G30: =SUM(G22:G24) -> 0 | H30: =SUM(H22:H24) -> 0
B31: Inward Supplies
C32: ITC (As per books) | H32: 0
C33: ITC as per GSTR 2B | D33: 0 | E33: 0 | F33: 0 | G33: 0 | H33: =SUM(E33:G33) -> 0
C34: (+) Import purchase | D34: 0 | E34: 0 | F34: 0 | G34: 0 | H34: =SUM(E34:G34) -> 0
C35: (+) RCM paid on Inward Supplies | D35: =D24 -> 0 | E35: =E24 -> 0 | F35: =F24 -> 0 | G35: =G24 -> 0 | H35: =SUM(E35:G35) -> 0
C36: (+) Credit Notes | D36: 0 | E36: 0 | F36: 0 | G36: 0 | H36: =SUM(E36:G36) -> 0
C37: (+) Opening Credit Balance | D37: 0 | E37: ='April-2026'!E50 -> 0 | F37: ='April-2026'!F50 -> 0 | G37: ='April-2026'!G50 -> 0 | H37: =SUM(E37:G37) -> 0
C38: (-) Debit Notes | D38: 0 | E38: 0 | F38: 0 | G38: 0 | H38: =SUM(E38:G38) -> 0
C39: (-) ITC Reversed on Ineligible credit | D39: 0 | E39: 0 | F39: 0 | G39: 0 | H39: =SUM(E39:G39) -> 0
C41: (B) Total ITC Available for Set off | D41: =SUM(D33:D37)-SUM(D38:D39) -> 0 | E41: =SUM(E33:E37)-SUM(E38:E39) -> 0 | F41: =SUM(F33:F37)-SUM(F38:F39) -> 0 | G41: =SUM(G33:G37)-SUM(G38:G39) -> 0 | H41: =SUM(H33:H37)-SUM(H38:H39) -> 0
B43: Tax Set-off | C43: (A-B) Payable | E43: =E22-E41 -> 0 | F43: =F22-F41 -> 0 | G43: =G22-G41 -> 0 | H43: =H22-H41 -> 0
C44: (-) Adjustment | E44: 0 | F44: 0 | G44: 0 | H44: =SUM(E44:G44) -> 0
C46: (-) GST TDS/TCS Opening Cash Balance | E46: 0 | F46: 0 | G46: 0 | H46: =SUM(D46:G46) -> 0
C48: Final Liability Payable | E48: =IF(E43-E44>0,E43-E44,0)-E46 -> 0 | F48: =IF(F43-F44>0,F43-F44,0)-F46 -> 0 | G48: =IF(G43-G44>0,G43-G44,0)-G46 -> 0 | H48: =IF(H43-H44>0,H43-H44,0)-H46 -> 0
C50: Balance C/f to next month | E50: =IF(E43-E44<0,E44-E43,0) -> 0 | F50: =IF(F43-F44<0,F44-F43,0) -> 0 | G50: =IF(G43-G44<0,G44-G43,0) -> 0 | H50: =SUM(E50:G50) -> 0
...

Sheet June-2026
G1: June
B2: DYP INFRAPROJECTS PRIVATE LIMITED
B3: GST No. 27AAGCD4105L1ZO
B5: GSTR-3B WORKING FOR THE MONTH OF JUNE 2026
B6: PARTICULARS | D6: TAXABLE | E6: CGST | F6: SGST | G6: IGST | H6: TOTAL
B8: Outward Supply | C8: Sales (B2B) | D8: 0 | E8: 0 | F8: 0 | G8: 0 | H8: =SUM(E8:G8) -> 0
C9: Sales (B2C) | D9: 0 | E9: 0 | F9: 0 | G9: 0 | H9: =SUM(E9:G9) -> 0
C10: SEZ supply with payment | D10: 0 | E10: 0 | F10: 0 | G10: 0 | H10: =SUM(E10:G10) -> 0
C11: SEZ supply without-payment | D11: 0 | E11: 0 | F11: 0 | G11: 0 | H11: =SUM(E11:G11) -> 0
C12: Zero Rated Supply/Export Sale | D12: 0 | E12: 0 | F12: 0 | G12: 0 | H12: =SUM(E12:G12) -> 0
C13: Nil Rated Supply | D13: 0 | E13: 0 | F13: 0 | G13: 0 | H13: =SUM(E13:G13) -> 0
C14: Exempt Sale | D14: 0 | E14: 0 | F14: 0 | G14: 0 | H14: =SUM(E14:G14) -> 0
C15: Advances Collected for Services | D15: 0 | E15: 0 | F15: 0 | G15: 0 | H15: =SUM(E15:G15) -> 0
C16: Rent Received | D16: 0 | E16: 0 | F16: 0 | G16: 0 | H16: =SUM(E16:G16) -> 0
C17: Sale Increased through Amendment | D17: 0 | E17: 0 | F17: 0 | G17: 0 | H17: =SUM(E17:G17) -> 0
C18: (-) Sale Decreased through Amendment | D18: 0 | E18: 0 | F18: 0 | G18: 0 | H18: =SUM(E18:G18) -> 0
C19: (-) Credit Note | D19: 0 | E19: 0 | F19: 0 | G19: 0 | H19: =SUM(E19:G19) -> 0
C20: (-) Advances Settled Against Services | D20: 0 | E20: 0 | F20: 0 | G20: 0 | H20: =SUM(E20:G20) -> 0
C22: Total Sale as per Working | D22: =SUM(D8:D17)-SUM(D18:D20) -> 0 | E22: =SUM(E8:E17)-SUM(E18:E20) -> 0 | F22: =SUM(F8:F17)-SUM(F18:F20) -> 0 | G22: =SUM(G8:G17)-SUM(G18:G20) -> 0 | H22: =SUM(H8:H17)-SUM(H18:H20) -> 0
C24: Reverse Charge on Inward Supplies | D24: =SUM(D25:D28) -> 0 | E24: =SUM(E25:E28) -> 0 | F24: =SUM(F25:F28) -> 0 | G24: =SUM(G25:G28) -> 0 | H24: =SUM(H25:H28) -> 0
C25: RCM on Transport Charges 5% | D25: 0 | E25: 0 | F25: 0 | G25: 0 | H25: =SUM(E25:G25) -> 0
C26: RCM on Security Charges 18% | D26: 0 | E26: 0 | F26: 0 | G26: 0 | H26: =SUM(E26:G26) -> 0
C27: RCM on Guest House Charges 18% | D27: 0 | E27: 0 | F27: 0 | G27: 0 | H27: =SUM(E27:G27) -> 0
C28: RCM on Advocate Charges 18% | D28: 0 | E28: 0 | F28: 0 | G28: 0 | H28: =SUM(E28:G28) -> 0
C30: (A) Total Sale as per Working including Reverse Charge | D30: =SUM(D22:D24) -> 0 | E30: =SUM(E22:E24) -> 0 | F30: =SUM(F22:F24) -> 0 | G30: =SUM(G22:G24) -> 0 | H30: =SUM(H22:H24) -> 0
B31: Inward Supplies
C32: ITC (As per books) | H32: 0
C33: ITC as per GSTR 2B | D33: 0 | E33: 0 | F33: 0 | G33: 0 | H33: =SUM(E33:G33) -> 0
C34: (+) Import purchase | D34: 0 | E34: 0 | F34: 0 | G34: 0 | H34: =SUM(E34:G34) -> 0
C35: (+) RCM paid on Inward Supplies | D35: =D24 -> 0 | E35: =E24 -> 0 | F35: =F24 -> 0 | G35: =G24 -> 0 | H35: =SUM(E35:G35) -> 0
C36: (+) Credit Notes | D36: 0 | E36: 0 | F36: 0 | G36: 0 | H36: =SUM(E36:G36) -> 0
C37: (+) Opening Credit Balance | D37: 0 | E37: ='May-2026'!E50 -> 0 | F37: ='May-2026'!F50 -> 0 | G37: ='May-2026'!G50 -> 0 | H37: =SUM(E37:G37) -> 0
C38: (-) Debit Notes | D38: 0 | E38: 0 | F38: 0 | G38: 0 | H38: =SUM(E38:G38) -> 0
C39: (-) ITC Reversed on Ineligible credit | D39: 0 | E39: 0 | F39: 0 | G39: 0 | H39: =SUM(E39:G39) -> 0
C41: (B) Total ITC Available for Set off | D41: =SUM(D33:D37)-SUM(D38:D39) -> 0 | E41: =SUM(E33:E37)-SUM(E38:E39) -> 0 | F41: =SUM(F33:F37)-SUM(F38:F39) -> 0 | G41: =SUM(G33:G37)-SUM(G38:G39) -> 0 | H41: =SUM(H33:H37)-SUM(H38:H39) -> 0
B43: Tax Set-off | C43: (A-B) Payable | E43: =E22-E41 -> 0 | F43: =F22-F41 -> 0 | G43: =G22-G41 -> 0 | H43: =H22-H41 -> 0
C44: (-) Adjustment | E44: 0 | F44: 0 | G44: 0 | H44: =SUM(E44:G44) -> 0
C46: (-) GST TDS/TCS Opening Cash Balance | E46: 0 | F46: 0 | G46: 0 | H46: =SUM(D46:G46) -> 0
C48: Final Liability Payable | E48: =IF(E43-E44>0,E43-E44,0)-E46 -> 0 | F48: =IF(F43-F44>0,F43-F44,0)-F46 -> 0 | G48: =IF(G43-G44>0,G43-G44,0)-G46 -> 0 | H48: =IF(H43-H44>0,H43-H44,0)-H46 -> 0
C50: Balance C/f to next month | E50: =IF(E43-E44<0,E44-E43,0) -> 0 | F50: =IF(F43-F44<0,F44-F43,0) -> 0 | G50: =IF(G43-G44<0,G44-G43,0) -> 0 | H50: =SUM(E50:G50) -> 0
...

Sheet July-2026
G1: July
B2: DYP INFRAPROJECTS PRIVATE LIMITED
B3: GST No. 27AAGCD4105L1ZO
B5: GSTR-3B WORKING FOR THE MONTH OF JULY 2026
B6: PARTICULARS | D6: TAXABLE | E6: CGST | F6: SGST | G6: IGST | H6: TOTAL
B8: Outward Supply | C8: Sales (B2B) | D8: 0 | E8: 0 | F8: 0 | G8: 0 | H8: =SUM(E8:G8) -> 0
C9: Sales (B2C) | D9: 0 | E9: 0 | F9: 0 | G9: 0 | H9: =SUM(E9:G9) -> 0
C10: SEZ supply with payment | D10: 0 | E10: 0 | F10: 0 | G10: 0 | H10: =SUM(E10:G10) -> 0
C11: SEZ supply without-payment | D11: 0 | E11: 0 | F11: 0 | G11: 0 | H11: =SUM(E11:G11) -> 0
C12: Zero Rated Supply/Export Sale | D12: 0 | E12: 0 | F12: 0 | G12: 0 | H12: =SUM(E12:G12) -> 0
C13: Nil Rated Supply | D13: 0 | E13: 0 | F13: 0 | G13: 0 | H13: =SUM(E13:G13) -> 0
C14: Exempt Sale | D14: 0 | E14: 0 | F14: 0 | G14: 0 | H14: =SUM(E14:G14) -> 0
C15: Advances Collected for Services | D15: 0 | E15: 0 | F15: 0 | G15: 0 | H15: =SUM(E15:G15) -> 0
C16: Rent Received | D16: 0 | E16: 0 | F16: 0 | G16: 0 | H16: =SUM(E16:G16) -> 0
C17: Sale Increased through Amendment | D17: 0 | E17: 0 | F17: 0 | G17: 0 | H17: =SUM(E17:G17) -> 0
C18: (-) Sale Decreased through Amendment | D18: 0 | E18: 0 | F18: 0 | G18: 0 | H18: =SUM(E18:G18) -> 0
C19: (-) Credit Note | D19: 0 | E19: 0 | F19: 0 | G19: 0 | H19: =SUM(E19:G19) -> 0
C20: (-) Advances Settled Against Services | D20: 0 | E20: 0 | F20: 0 | G20: 0 | H20: =SUM(E20:G20) -> 0
C22: Total Sale as per Working | D22: =SUM(D8:D17)-SUM(D18:D20) -> 0 | E22: =SUM(E8:E17)-SUM(E18:E20) -> 0 | F22: =SUM(F8:F17)-SUM(F18:F20) -> 0 | G22: =SUM(G8:G17)-SUM(G18:G20) -> 0 | H22: =SUM(H8:H17)-SUM(H18:H20) -> 0
C24: Reverse Charge on Inward Supplies | D24: =SUM(D25:D28) -> 0 | E24: =SUM(E25:E28) -> 0 | F24: =SUM(F25:F28) -> 0 | G24: =SUM(G25:G28) -> 0 | H24: =SUM(H25:H28) -> 0
C25: RCM on Transport Charges 5% | D25: 0 | E25: 0 | F25: 0 | G25: 0 | H25: =SUM(E25:G25) -> 0
C26: RCM on Security Charges 18% | D26: 0 | E26: 0 | F26: 0 | G26: 0 | H26: =SUM(E26:G26) -> 0
C27: RCM on Guest House Charges 18% | D27: 0 | E27: 0 | F27: 0 | G27: 0 | H27: =SUM(E27:G27) -> 0
C28: RCM on Advocate Charges 18% | D28: 0 | E28: 0 | F28: 0 | G28: 0 | H28: =SUM(E28:G28) -> 0
C30: (A) Total Sale as per Working including Reverse Charge | D30: =SUM(D22:D24) -> 0 | E30: =SUM(E22:E24) -> 0 | F30: =SUM(F22:F24) -> 0 | G30: =SUM(G22:G24) -> 0 | H30: =SUM(H22:H24) -> 0
B31: Inward Supplies
C32: ITC (As per books) | H32: 0
C33: ITC as per GSTR 2B | D33: 0 | E33: 0 | F33: 0 | G33: 0 | H33: =SUM(E33:G33) -> 0
C34: (+) Import purchase | D34: 0 | E34: 0 | F34: 0 | G34: 0 | H34: =SUM(E34:G34) -> 0
C35: (+) RCM paid on Inward Supplies | D35: =D24 -> 0 | E35: =E24 -> 0 | F35: =F24 -> 0 | G35: =G24 -> 0 | H35: =SUM(E35:G35) -> 0
C36: (+) Credit Notes | D36: 0 | E36: 0 | F36: 0 | G36: 0 | H36: =SUM(E36:G36) -> 0
C37: (+) Opening Credit Balance | D37: 0 | E37: ='June-2026'!E50 -> 0 | F37: ='June-2026'!F50 -> 0 | G37: ='June-2026'!G50 -> 0 | H37: =SUM(E37:G37) -> 0
C38: (-) Debit Notes | D38: 0 | E38: 0 | F38: 0 | G38: 0 | H38: =SUM(E38:G38) -> 0
C39: (-) ITC Reversed on Ineligible credit | D39: 0 | E39: 0 | F39: 0 | G39: 0 | H39: =SUM(E39:G39) -> 0
C41: (B) Total ITC Available for Set off | D41: =SUM(D33:D37)-SUM(D38:D39) -> 0 | E41: =SUM(E33:E37)-SUM(E38:E39) -> 0 | F41: =SUM(F33:F37)-SUM(F38:F39) -> 0 | G41: =SUM(G33:G37)-SUM(G38:G39) -> 0 | H41: =SUM(H33:H37)-SUM(H38:H39) -> 0
B43: Tax Set-off | C43: (A-B) Payable | E43: =E22-E41 -> 0 | F43: =F22-F41 -> 0 | G43: =G22-G41 -> 0 | H43: =H22-H41 -> 0
C44: (-) Adjustment | E44: 0 | F44: 0 | G44: 0 | H44: =SUM(E44:G44) -> 0
C46: (-) GST TDS/TCS Opening Cash Balance | E46: 0 | F46: 0 | G46: 0 | H46: =SUM(D46:G46) -> 0
C48: Final Liability Payable | E48: =IF(E43-E44>0,E43-E44,0)-E46 -> 0 | F48: =IF(F43-F44>0,F43-F44,0)-F46 -> 0 | G48: =IF(G43-G44>0,G43-G44,0)-G46 -> 0 | H48: =IF(H43-H44>0,H43-H44,0)-H46 -> 0
C50: Balance C/f to next month | E50: =IF(E43-E44<0,E44-E43,0) -> 0 | F50: =IF(F43-F44<0,F44-F43,0) -> 0 | G50: =IF(G43-G44<0,G44-G43,0) -> 0 | H50: =SUM(E50:G50) -> 0
...

Sheet August-2026
G1: August
B2: DYP INFRAPROJECTS PRIVATE LIMITED
B3: GST No. 27AAGCD4105L1ZO
B5: GSTR-3B WORKING FOR THE MONTH OF AUGUST 2026
B6: PARTICULARS | D6: TAXABLE | E6: CGST | F6: SGST | G6: IGST | H6: TOTAL
B8: Outward Supply | C8: Sales (B2B) | D8: 0 | E8: 0 | F8: 0 | G8: 0 | H8: =SUM(E8:G8) -> 0
C9: Sales (B2C) | D9: 0 | E9: 0 | F9: 0 | G9: 0 | H9: =SUM(E9:G9) -> 0
C10: SEZ supply with payment | D10: 0 | E10: 0 | F10: 0 | G10: 0 | H10: =SUM(E10:G10) -> 0
C11: SEZ supply without-payment | D11: 0 | E11: 0 | F11: 0 | G11: 0 | H11: =SUM(E11:G11) -> 0
C12: Zero Rated Supply/Export Sale | D12: 0 | E12: 0 | F12: 0 | G12: 0 | H12: =SUM(E12:G12) -> 0
C13: Nil Rated Supply | D13: 0 | E13: 0 | F13: 0 | G13: 0 | H13: =SUM(E13:G13) -> 0
C14: Exempt Sale | D14: 0 | E14: 0 | F14: 0 | G14: 0 | H14: =SUM(E14:G14) -> 0
C15: Advances Collected for Services | D15: 0 | E15: 0 | F15: 0 | G15: 0 | H15: =SUM(E15:G15) -> 0
C16: Rent Received | D16: 0 | E16: 0 | F16: 0 | G16: 0 | H16: =SUM(E16:G16) -> 0
C17: Sale Increased through Amendment | D17: 0 | E17: 0 | F17: 0 | G17: 0 | H17: =SUM(E17:G17) -> 0
C18: (-) Sale Decreased through Amendment | D18: 0 | E18: 0 | F18: 0 | G18: 0 | H18: =SUM(E18:G18) -> 0
C19: (-) Credit Note | D19: 0 | E19: 0 | F19: 0 | G19: 0 | H19: =SUM(E19:G19) -> 0
C20: (-) Advances Settled Against Services | D20: 0 | E20: 0 | F20: 0 | G20: 0 | H20: =SUM(E20:G20) -> 0
C22: Total Sale as per Working | D22: =SUM(D8:D17)-SUM(D18:D20) -> 0 | E22: =SUM(E8:E17)-SUM(E18:E20) -> 0 | F22: =SUM(F8:F17)-SUM(F18:F20) -> 0 | G22: =SUM(G8:G17)-SUM(G18:G20) -> 0 | H22: =SUM(H8:H17)-SUM(H18:H20) -> 0
C24: Reverse Charge on Inward Supplies | D24: =SUM(D25:D28) -> 0 | E24: =SUM(E25:E28) -> 0 | F24: =SUM(F25:F28) -> 0 | G24: =SUM(G25:G28) -> 0 | H24: =SUM(H25:H28) -> 0
C25: RCM on Transport Charges 5% | D25: 0 | E25: 0 | F25: 0 | G25: 0 | H25: =SUM(E25:G25) -> 0
C26: RCM on Security Charges 18% | D26: 0 | E26: 0 | F26: 0 | G26: 0 | H26: =SUM(E26:G26) -> 0
C27: RCM on Guest House Charges 18% | D27: 0 | E27: 0 | F27: 0 | G27: 0 | H27: =SUM(E27:G27) -> 0
C28: RCM on Advocate Charges 18% | D28: 0 | E28: 0 | F28: 0 | G28: 0 | H28: =SUM(E28:G28) -> 0
C30: (A) Total Sale as per Working including Reverse Charge | D30: =SUM(D22:D24) -> 0 | E30: =SUM(E22:E24) -> 0 | F30: =SUM(F22:F24) -> 0 | G30: =SUM(G22:G24) -> 0 | H30: =SUM(H22:H24) -> 0
B31: Inward Supplies
C32: ITC (As per books) | H32: 0
C33: ITC as per GSTR 2B | D33: 0 | E33: 0 | F33: 0 | G33: 0 | H33: =SUM(E33:G33) -> 0
C34: (+) Import purchase | D34: 0 | E34: 0 | F34: 0 | G34: 0 | H34: =SUM(E34:G34) -> 0
C35: (+) RCM paid on Inward Supplies | D35: =D24 -> 0 | E35: =E24 -> 0 | F35: =F24 -> 0 | G35: =G24 -> 0 | H35: =SUM(E35:G35) -> 0
C36: (+) Credit Notes | D36: 0 | E36: 0 | F36: 0 | G36: 0 | H36: =SUM(E36:G36) -> 0
C37: (+) Opening Credit Balance | D37: 0 | E37: ='July-2026'!E50 -> 0 | F37: ='July-2026'!F50 -> 0 | G37: ='July-2026'!G50 -> 0 | H37: =SUM(E37:G37) -> 0
C38: (-) Debit Notes | D38: 0 | E38: 0 | F38: 0 | G38: 0 | H38: =SUM(E38:G38) -> 0
C39: (-) ITC Reversed on Ineligible credit | D39: 0 | E39: 0 | F39: 0 | G39: 0 | H39: =SUM(E39:G39) -> 0
C41: (B) Total ITC Available for Set off | D41: =SUM(D33:D37)-SUM(D38:D39) -> 0 | E41: =SUM(E33:E37)-SUM(E38:E39) -> 0 | F41: =SUM(F33:F37)-SUM(F38:F39) -> 0 | G41: =SUM(G33:G37)-SUM(G38:G39) -> 0 | H41: =SUM(H33:H37)-SUM(H38:H39) -> 0
B43: Tax Set-off | C43: (A-B) Payable | E43: =E22-E41 -> 0 | F43: =F22-F41 -> 0 | G43: =G22-G41 -> 0 | H43: =H22-H41 -> 0
C44: (-) Adjustment | E44: 0 | F44: 0 | G44: 0 | H44: =SUM(E44:G44) -> 0
C46: (-) GST TDS/TCS Opening Cash Balance | E46: 0 | F46: 0 | G46: 0 | H46: =SUM(D46:G46) -> 0
C48: Final Liability Payable | E48: =IF(E43-E44>0,E43-E44,0)-E46 -> 0 | F48: =IF(F43-F44>0,F43-F44,0)-F46 -> 0 | G48: =IF(G43-G44>0,G43-G44,0)-G46 -> 0 | H48: =IF(H43-H44>0,H43-H44,0)-H46 -> 0
C50: Balance C/f to next month | E50: =IF(E43-E44<0,E44-E43,0) -> 0 | F50: =IF(F43-F44<0,F44-F43,0) -> 0 | G50: =IF(G43-G44<0,G44-G43,0) -> 0 | H50: =SUM(E50:G50) -> 0
...

Sheet September-2026
G1: September
B2: DYP INFRAPROJECTS PRIVATE LIMITED
B3: GST No. 27AAGCD4105L1ZO
B5: GSTR-3B WORKING FOR THE MONTH OF SEPTEMBER 2026
B6: PARTICULARS | D6: TAXABLE | E6: CGST | F6: SGST | G6: IGST | H6: TOTAL
B8: Outward Supply | C8: Sales (B2B) | D8: 20018169 | E8: 1795036 | F8: 1795036 | G8: 0 | H8: =SUM(E8:G8) -> 3590072
C9: Sales (B2C) | D9: 491948 | E9: 44275.32 | F9: 44275.32 | G9: 0 | H9: =SUM(E9:G9) -> 88550.64
C10: SEZ supply with payment | D10: 0 | E10: 0 | F10: 0 | G10: 0 | H10: =SUM(E10:G10) -> 0
C11: SEZ supply without-payment | D11: 0 | E11: 0 | F11: 0 | G11: 0 | H11: =SUM(E11:G11) -> 0
C12: Zero Rated Supply/Export Sale | D12: 0 | E12: 0 | F12: 0 | G12: 0 | H12: =SUM(E12:G12) -> 0
C13: Nil Rated Supply | D13: 0 | E13: 0 | F13: 0 | G13: 0 | H13: =SUM(E13:G13) -> 0
C14: Exempt Sale | D14: 0 | E14: 0 | F14: 0 | G14: 0 | H14: =SUM(E14:G14) -> 0
C15: Advances Collected for Services | D15: 0 | E15: 0 | F15: 0 | G15: 0 | H15: =SUM(E15:G15) -> 0
C16: Rent Received | D16: 0 | E16: 0 | F16: 0 | G16: 0 | H16: =SUM(E16:G16) -> 0
C17: Sale Increased through Amendment | D17: 0 | E17: 0 | F17: 0 | G17: 0 | H17: =SUM(E17:G17) -> 0
C18: (-) Sale Decreased through Amendment | D18: 0 | E18: 0 | F18: 0 | G18: 0 | H18: =SUM(E18:G18) -> 0
C19: (-) Credit Note | D19: 0 | E19: 0 | F19: 0 | G19: 0 | H19: =SUM(E19:G19) -> 0
C20: (-) Advances Settled Against Services | D20: 0 | E20: 0 | F20: 0 | G20: 0 | H20: =SUM(E20:G20) -> 0
C22: Total Sale as per Working | D22: =SUM(D8:D17)-SUM(D18:D20) -> 20510117 | E22: =SUM(E8:E17)-SUM(E18:E20) -> 1839311.3 | F22: =SUM(F8:F17)-SUM(F18:F20) -> 1839311.3 | G22: =SUM(G8:G17)-SUM(G18:G20) -> 0 | H22: =SUM(H8:H17)-SUM(H18:H20) -> 3678622.6
C24: Reverse Charge on Inward Supplies | D24: =SUM(D25:D28) -> 76310 | E24: =SUM(E25:E28) -> 5183.76 | F24: =SUM(F25:F28) -> 5183.76 | G24: =SUM(G25:G28) -> 0 | H24: =SUM(H25:H28) -> 10367.52
C25: RCM on Transport Charges 5% | D25: 76310 | E25: 5183.76 | F25: 5183.76 | G25: 0 | H25: =SUM(E25:G25) -> 10367.52
C26: RCM on Security Charges 18% | D26: 0 | E26: 0 | F26: 0 | G26: 0 | H26: =SUM(E26:G26) -> 0
C27: RCM on Guest House Charges 18% | D27: 0 | E27: 0 | F27: 0 | G27: 0 | H27: =SUM(E27:G27) -> 0
C28: RCM on Advocate Charges 18% | D28: 0 | E28: 0 | F28: 0 | G28: 0 | H28: =SUM(E28:G28) -> 0
C30: (A) Total Sale as per Working including Reverse Charge | D30: =SUM(D22:D24) -> 20586427 | E30: =SUM(E22:E24) -> 1844495.1 | F30: =SUM(F22:F24) -> 1844495.1 | G30: =SUM(G22:G24) -> 0 | H30: =SUM(H22:H24) -> 3688990.1
B31: Inward Supplies
C32: ITC (As per books) | H32: 0
C33: ITC as per GSTR 2B | D33: 6356996.8 | E33: 424030.14 | F33: 424030.14 | G33: 113124.55 | H33: =SUM(E33:G33) -> 961184.83
C34: (+) Import purchase | D34: 0 | E34: 0 | F34: 0 | G34: 0 | H34: =SUM(E34:G34) -> 0
C35: (+) RCM paid on Inward Supplies | D35: =D24 -> 76310 | E35: =E24 -> 5183.76 | F35: =F24 -> 5183.76 | G35: =G24 -> 0 | H35: =SUM(E35:G35) -> 10367.52
C36: (+) Credit Notes | D36: 0 | E36: 0 | F36: 0 | G36: 0 | H36: =SUM(E36:G36) -> 0
C37: (+) Opening Credit Balance | D37: 0 | E37: ='August-2026'!E50 -> 0 | F37: ='August-2026'!F50 -> 0 | G37: ='August-2026'!G50 -> 0 | H37: =SUM(E37:G37) -> 0
C38: (-) Debit Notes | D38: 13800 | E38: 864 | F38: 864 | G38: 0 | H38: =SUM(E38:G38) -> 1728
C39: (-) ITC Reversed on Ineligible credit | D39: 0 | E39: 1881 | F39: 1881 | G39: 0 | H39: =SUM(E39:G39) -> 3762
C41: (B) Total ITC Available for Set off | D41: =SUM(D33:D37)-SUM(D38:D39) -> 6419506.8 | E41: =SUM(E33:E37)-SUM(E38:E39) -> 426468.9 | F41: =SUM(F33:F37)-SUM(F38:F39) -> 426468.9 | G41: =SUM(G33:G37)-SUM(G38:G39) -> 113124.55 | H41: =SUM(H33:H37)-SUM(H38:H39) -> 966062.35
B43: Tax Set-off | C43: (A-B) Payable | E43: =E22-E41 -> 1412842.4 | F43: =F22-F41 -> 1412842.4 | G43: =G22-G41 -> -113124.55 | H43: =H22-H41 -> 2712560.2
C44: (-) Adjustment | E44: 113124.55 | F44: 0 | G44: -113124.55 | H44: =SUM(E44:G44) -> 0
C46: (-) GST TDS/TCS Opening Cash Balance | E46: 28285 | F46: 28285 | G46: 0 | H46: =SUM(D46:G46) -> 56570
C48: Final Liability Payable | E48: =IF(E43-E44>0,E43-E44,0)-E46 -> 1271432.9 | F48: =IF(F43-F44>0,F43-F44,0)-F46 -> 1384557.4 | G48: =IF(G43-G44>0,G43-G44,0)-G46 -> 0 | H48: =IF(H43-H44>0,H43-H44,0)-H46 -> 2655990.2
C50: Balance C/f to next month | E50: =IF(E43-E44<0,E44-E43,0) -> 0 | F50: =IF(F43-F44<0,F44-F43,0) -> 0 | G50: =IF(G43-G44<0,G44-G43,0) -> 0 | H50: =SUM(E50:G50) -> 0
...

Sheet October-2026
G1: October
B2: DYP INFRAPROJECTS PRIVATE LIMITED
B3: GST No. 27AAGCD4105L1ZO
B5: GSTR-3B WORKING FOR THE MONTH OF OCTOBER 2026
B6: PARTICULARS | D6: TAXABLE | E6: CGST | F6: SGST | G6: IGST | H6: TOTAL
B8: Outward Supply | C8: Sales (B2B) | D8: 0 | E8: 0 | F8: 0 | G8: 0 | H8: =SUM(E8:G8) -> 0
C9: Sales (B2C) | D9: 0 | E9: 0 | F9: 0 | G9: 0 | H9: =SUM(E9:G9) -> 0
C10: SEZ supply with payment | D10: 0 | E10: 0 | F10: 0 | G10: 0 | H10: =SUM(E10:G10) -> 0
C11: SEZ supply without-payment | D11: 0 | E11: 0 | F11: 0 | G11: 0 | H11: =SUM(E11:G11) -> 0
C12: Zero Rated Supply/Export Sale | D12: 0 | E12: 0 | F12: 0 | G12: 0 | H12: =SUM(E12:G12) -> 0
C13: Nil Rated Supply | D13: 0 | E13: 0 | F13: 0 | G13: 0 | H13: =SUM(E13:G13) -> 0
C14: Exempt Sale | D14: 0 | E14: 0 | F14: 0 | G14: 0 | H14: =SUM(E14:G14) -> 0
C15: Advances Collected for Services | D15: 0 | E15: 0 | F15: 0 | G15: 0 | H15: =SUM(E15:G15) -> 0
C16: Rent Received | D16: 0 | E16: 0 | F16: 0 | G16: 0 | H16: =SUM(E16:G16) -> 0
C17: Sale Increased through Amendment | D17: 0 | E17: 0 | F17: 0 | G17: 0 | H17: =SUM(E17:G17) -> 0
C18: (-) Sale Decreased through Amendment | D18: 0 | E18: 0 | F18: 0 | G18: 0 | H18: =SUM(E18:G18) -> 0
C19: (-) Credit Note | D19: 0 | E19: 0 | F19: 0 | G19: 0 | H19: =SUM(E19:G19) -> 0
C20: (-) Advances Settled Against Services | D20: 0 | E20: 0 | F20: 0 | G20: 0 | H20: =SUM(E20:G20) -> 0
C22: Total Sale as per Working | D22: =SUM(D8:D17)-SUM(D18:D20) -> 0 | E22: =SUM(E8:E17)-SUM(E18:E20) -> 0 | F22: =SUM(F8:F17)-SUM(F18:F20) -> 0 | G22: =SUM(G8:G17)-SUM(G18:G20) -> 0 | H22: =SUM(H8:H17)-SUM(H18:H20) -> 0
C24: Reverse Charge on Inward Supplies | D24: =SUM(D25:D28) -> 0 | E24: =SUM(E25:E28) -> 0 | F24: =SUM(F25:F28) -> 0 | G24: =SUM(G25:G28) -> 0 | H24: =SUM(H25:H28) -> 0
C25: RCM on Transport Charges 5% | D25: 0 | E25: 0 | F25: 0 | G25: 0 | H25: =SUM(E25:G25) -> 0
C26: RCM on Security Charges 18% | D26: 0 | E26: 0 | F26: 0 | G26: 0 | H26: =SUM(E26:G26) -> 0
C27: RCM on Guest House Charges 18% | D27: 0 | E27: 0 | F27: 0 | G27: 0 | H27: =SUM(E27:G27) -> 0
C28: RCM on Advocate Charges 18% | D28: 0 | E28: 0 | F28: 0 | G28: 0 | H28: =SUM(E28:G28) -> 0
C30: (A) Total Sale as per Working including Reverse Charge | D30: =SUM(D22:D24) -> 0 | E30: =SUM(E22:E24) -> 0 | F30: =SUM(F22:F24) -> 0 | G30: =SUM(G22:G24) -> 0 | H30: =SUM(H22:H24) -> 0
B31: Inward Supplies
C32: ITC (As per books) | H32: 0
C33: ITC as per GSTR 2B | D33: 0 | E33: 0 | F33: 0 | G33: 0 | H33: =SUM(E33:G33) -> 0
C34: (+) Import purchase | D34: 0 | E34: 0 | F34: 0 | G34: 0 | H34: =SUM(E34:G34) -> 0
C35: (+) RCM paid on Inward Supplies | D35: =D24 -> 0 | E35: =E24 -> 0 | F35: =F24 -> 0 | G35: =G24 -> 0 | H35: =SUM(E35:G35) -> 0
C36: (+) Credit Notes | D36: 0 | E36: 0 | F36: 0 | G36: 0 | H36: =SUM(E36:G36) -> 0
C37: (+) Opening Credit Balance | D37: 0 | E37: ='September-2026'!E50 -> 0 | F37: ='September-2026'!F50 -> 0 | G37: ='September-2026'!G50 -> 0 | H37: =SUM(E37:G37) -> 0
C38: (-) Debit Notes | D38: 0 | E38: 0 | F38: 0 | G38: 0 | H38: =SUM(E38:G38) -> 0
C39: (-) ITC Reversed on Ineligible credit | D39: 0 | E39: 0 | F39: 0 | G39: 0 | H39: =SUM(E39:G39) -> 0
C41: (B) Total ITC Available for Set off | D41: =SUM(D33:D37)-SUM(D38:D39) -> 0 | E41: =SUM(E33:E37)-SUM(E38:E39) -> 0 | F41: =SUM(F33:F37)-SUM(F38:F39) -> 0 | G41: =SUM(G33:G37)-SUM(G38:G39) -> 0 | H41: =SUM(H33:H37)-SUM(H38:H39) -> 0
B43: Tax Set-off | C43: (A-B) Payable | E43: =E22-E41 -> 0 | F43: =F22-F41 -> 0 | G43: =G22-G41 -> 0 | H43: =H22-H41 -> 0
C44: (-) Adjustment | E44: 0 | F44: 0 | G44: 0 | H44: =SUM(E44:G44) -> 0
C46: (-) GST TDS/TCS Opening Cash Balance | E46: 0 | F46: 0 | G46: 0 | H46: =SUM(D46:G46) -> 0
C48: Final Liability Payable | E48: =IF(E43-E44>0,E43-E44,0)-E46 -> 0 | F48: =IF(F43-F44>0,F43-F44,0)-F46 -> 0 | G48: =IF(G43-G44>0,G43-G44,0)-G46 -> 0 | H48: =IF(H43-H44>0,H43-H44,0)-H46 -> 0
C50: Balance C/f to next month | E50: =IF(E43-E44<0,E44-E43,0) -> 0 | F50: =IF(F43-F44<0,F44-F43,0) -> 0 | G50: =IF(G43-G44<0,G44-G43,0) -> 0 | H50: =SUM(E50:G50) -> 0
...

Sheet November-2026
G1: November
B2: DYP INFRAPROJECTS PRIVATE LIMITED
B3: GST No. 27AAGCD4105L1ZO
B5: GSTR-3B WORKING FOR THE MONTH OF NOVEMBER 2026
B6: PARTICULARS | D6: TAXABLE | E6: CGST | F6: SGST | G6: IGST | H6: TOTAL
B8: Outward Supply | C8: Sales (B2B) | D8: 0 | E8: 0 | F8: 0 | G8: 0 | H8: =SUM(E8:G8) -> 0
C9: Sales (B2C) | D9: 0 | E9: 0 | F9: 0 | G9: 0 | H9: =SUM(E9:G9) -> 0
C10: SEZ supply with payment | D10: 0 | E10: 0 | F10: 0 | G10: 0 | H10: =SUM(E10:G10) -> 0
C11: SEZ supply without-payment | D11: 0 | E11: 0 | F11: 0 | G11: 0 | H11: =SUM(E11:G11) -> 0
C12: Zero Rated Supply/Export Sale | D12: 0 | E12: 0 | F12: 0 | G12: 0 | H12: =SUM(E12:G12) -> 0
C13: Nil Rated Supply | D13: 0 | E13: 0 | F13: 0 | G13: 0 | H13: =SUM(E13:G13) -> 0
C14: Exempt Sale | D14: 0 | E14: 0 | F14: 0 | G14: 0 | H14: =SUM(E14:G14) -> 0
C15: Advances Collected for Services | D15: 0 | E15: 0 | F15: 0 | G15: 0 | H15: =SUM(E15:G15) -> 0
C16: Rent Received | D16: 0 | E16: 0 | F16: 0 | G16: 0 | H16: =SUM(E16:G16) -> 0
C17: Sale Increased through Amendment | D17: 0 | E17: 0 | F17: 0 | G17: 0 | H17: =SUM(E17:G17) -> 0
C18: (-) Sale Decreased through Amendment | D18: 0 | E18: 0 | F18: 0 | G18: 0 | H18: =SUM(E18:G18) -> 0
C19: (-) Credit Note | D19: 0 | E19: 0 | F19: 0 | G19: 0 | H19: =SUM(E19:G19) -> 0
C20: (-) Advances Settled Against Services | D20: 0 | E20: 0 | F20: 0 | G20: 0 | H20: =SUM(E20:G20) -> 0
C22: Total Sale as per Working | D22: =SUM(D8:D17)-SUM(D18:D20) -> 0 | E22: =SUM(E8:E17)-SUM(E18:E20) -> 0 | F22: =SUM(F8:F17)-SUM(F18:F20) -> 0 | G22: =SUM(G8:G17)-SUM(G18:G20) -> 0 | H22: =SUM(H8:H17)-SUM(H18:H20) -> 0
C24: Reverse Charge on Inward Supplies | D24: =SUM(D25:D28) -> 0 | E24: =SUM(E25:E28) -> 0 | F24: =SUM(F25:F28) -> 0 | G24: =SUM(G25:G28) -> 0 | H24: =SUM(H25:H28) -> 0
C25: RCM on Transport Charges 5% | D25: 0 | E25: 0 | F25: 0 | G25: 0 | H25: =SUM(E25:G25) -> 0
C26: RCM on Security Charges 18% | D26: 0 | E26: 0 | F26: 0 | G26: 0 | H26: =SUM(E26:G26) -> 0
C27: RCM on Guest House Charges 18% | D27: 0 | E27: 0 | F27: 0 | G27: 0 | H27: =SUM(E27:G27) -> 0
C28: RCM on Advocate Charges 18% | D28: 0 | E28: 0 | F28: 0 | G28: 0 | H28: =SUM(E28:G28) -> 0
C30: (A) Total Sale as per Working including Reverse Charge | D30: =SUM(D22:D24) -> 0 | E30: =SUM(E22:E24) -> 0 | F30: =SUM(F22:F24) -> 0 | G30: =SUM(G22:G24) -> 0 | H30: =SUM(H22:H24) -> 0
B31: Inward Supplies
C32: ITC (As per books) | H32: 0
C33: ITC as per GSTR 2B | D33: 0 | E33: 0 | F33: 0 | G33: 0 | H33: =SUM(E33:G33) -> 0
C34: (+) Import purchase | D34: 0 | E34: 0 | F34: 0 | G34: 0 | H34: =SUM(E34:G34) -> 0
C35: (+) RCM paid on Inward Supplies | D35: =D24 -> 0 | E35: =E24 -> 0 | F35: =F24 -> 0 | G35: =G24 -> 0 | H35: =SUM(E35:G35) -> 0
C36: (+) Credit Notes | D36: 0 | E36: 0 | F36: 0 | G36: 0 | H36: =SUM(E36:G36) -> 0
C37: (+) Opening Credit Balance | D37: 0 | E37: ='October-2026'!E50 -> 0 | F37: ='October-2026'!F50 -> 0 | G37: ='October-2026'!G50 -> 0 | H37: =SUM(E37:G37) -> 0
C38: (-) Debit Notes | D38: 0 | E38: 0 | F38: 0 | G38: 0 | H38: =SUM(E38:G38) -> 0
C39: (-) ITC Reversed on Ineligible credit | D39: 0 | E39: 0 | F39: 0 | G39: 0 | H39: =SUM(E39:G39) -> 0
C41: (B) Total ITC Available for Set off | D41: =SUM(D33:D37)-SUM(D38:D39) -> 0 | E41: =SUM(E33:E37)-SUM(E38:E39) -> 0 | F41: =SUM(F33:F37)-SUM(F38:F39) -> 0 | G41: =SUM(G33:G37)-SUM(G38:G39) -> 0 | H41: =SUM(H33:H37)-SUM(H38:H39) -> 0
B43: Tax Set-off | C43: (A-B) Payable | E43: =E22-E41 -> 0 | F43: =F22-F41 -> 0 | G43: =G22-G41 -> 0 | H43: =H22-H41 -> 0
C44: (-) Adjustment | E44: 0 | F44: 0 | G44: 0 | H44: =SUM(E44:G44) -> 0
C46: (-) GST TDS/TCS Opening Cash Balance | E46: 0 | F46: 0 | G46: 0 | H46: =SUM(D46:G46) -> 0
C48: Final Liability Payable | E48: =IF(E43-E44>0,E43-E44,0)-E46 -> 0 | F48: =IF(F43-F44>0,F43-F44,0)-F46 -> 0 | G48: =IF(G43-G44>0,G43-G44,0)-G46 -> 0 | H48: =IF(H43-H44>0,H43-H44,0)-H46 -> 0
C50: Balance C/f to next month | E50: =IF(E43-E44<0,E44-E43,0) -> 0 | F50: =IF(F43-F44<0,F44-F43,0) -> 0 | G50: =IF(G43-G44<0,G44-G43,0) -> 0 | H50: =SUM(E50:G50) -> 0
...

Sheet December-2026
G1: December
B2: DYP INFRAPROJECTS PRIVATE LIMITED
B3: GST No. 27AAGCD4105L1ZO
B5: GSTR-3B WORKING FOR THE MONTH OF DECEMBER 2026
B6: PARTICULARS | D6: TAXABLE | E6: CGST | F6: SGST | G6: IGST | H6: TOTAL
B8: Outward Supply | C8: Sales (B2B) | D8: 0 | E8: 0 | F8: 0 | G8: 0 | H8: =SUM(E8:G8) -> 0
C9: Sales (B2C) | D9: 0 | E9: 0 | F9: 0 | G9: 0 | H9: =SUM(E9:G9) -> 0
C10: SEZ supply with payment | D10: 0 | E10: 0 | F10: 0 | G10: 0 | H10: =SUM(E10:G10) -> 0
C11: SEZ supply without-payment | D11: 0 | E11: 0 | F11: 0 | G11: 0 | H11: =SUM(E11:G11) -> 0
C12: Zero Rated Supply/Export Sale | D12: 0 | E12: 0 | F12: 0 | G12: 0 | H12: =SUM(E12:G12) -> 0
C13: Nil Rated Supply | D13: 0 | E13: 0 | F13: 0 | G13: 0 | H13: =SUM(E13:G13) -> 0
C14: Exempt Sale | D14: 0 | E14: 0 | F14: 0 | G14: 0 | H14: =SUM(E14:G14) -> 0
C15: Advances Collected for Services | D15: 0 | E15: 0 | F15: 0 | G15: 0 | H15: =SUM(E15:G15) -> 0
C16: Rent Received | D16: 0 | E16: 0 | F16: 0 | G16: 0 | H16: =SUM(E16:G16) -> 0
C17: Sale Increased through Amendment | D17: 0 | E17: 0 | F17: 0 | G17: 0 | H17: =SUM(E17:G17) -> 0
C18: (-) Sale Decreased through Amendment | D18: 0 | E18: 0 | F18: 0 | G18: 0 | H18: =SUM(E18:G18) -> 0
C19: (-) Credit Note | D19: 0 | E19: 0 | F19: 0 | G19: 0 | H19: =SUM(E19:G19) -> 0
C20: (-) Advances Settled Against Services | D20: 0 | E20: 0 | F20: 0 | G20: 0 | H20: =SUM(E20:G20) -> 0
C22: Total Sale as per Working | D22: =SUM(D8:D17)-SUM(D18:D20) -> 0 | E22: =SUM(E8:E17)-SUM(E18:E20) -> 0 | F22: =SUM(F8:F17)-SUM(F18:F20) -> 0 | G22: =SUM(G8:G17)-SUM(G18:G20) -> 0 | H22: =SUM(H8:H17)-SUM(H18:H20) -> 0
C24: Reverse Charge on Inward Supplies | D24: =SUM(D25:D28) -> 0 | E24: =SUM(E25:E28) -> 0 | F24: =SUM(F25:F28) -> 0 | G24: =SUM(G25:G28) -> 0 | H24: =SUM(H25:H28) -> 0
C25: RCM on Transport Charges 5% | D25: 0 | E25: 0 | F25: 0 | G25: 0 | H25: =SUM(E25:G25) -> 0
C26: RCM on Security Charges 18% | D26: 0 | E26: 0 | F26: 0 | G26: 0 | H26: =SUM(E26:G26) -> 0
C27: RCM on Guest House Charges 18% | D27: 0 | E27: 0 | F27: 0 | G27: 0 | H27: =SUM(E27:G27) -> 0
C28: RCM on Advocate Charges 18% | D28: 0 | E28: 0 | F28: 0 | G28: 0 | H28: =SUM(E28:G28) -> 0
C30: (A) Total Sale as per Working including Reverse Charge | D30: =SUM(D22:D24) -> 0 | E30: =SUM(E22:E24) -> 0 | F30: =SUM(F22:F24) -> 0 | G30: =SUM(G22:G24) -> 0 | H30: =SUM(H22:H24) -> 0
B31: Inward Supplies
C32: ITC (As per books) | H32: 0
C33: ITC as per GSTR 2B | D33: 0 | E33: 0 | F33: 0 | G33: 0 | H33: =SUM(E33:G33) -> 0
C34: (+) Import purchase | D34: 0 | E34: 0 | F34: 0 | G34: 0 | H34: =SUM(E34:G34) -> 0
C35: (+) RCM paid on Inward Supplies | D35: =D24 -> 0 | E35: =E24 -> 0 | F35: =F24 -> 0 | G35: =G24 -> 0 | H35: =SUM(E35:G35) -> 0
C36: (+) Credit Notes | D36: 0 | E36: 0 | F36: 0 | G36: 0 | H36: =SUM(E36:G36) -> 0
C37: (+) Opening Credit Balance | D37: 0 | E37: ='November-2026'!E50 -> 0 | F37: ='November-2026'!F50 -> 0 | G37: ='November-2026'!G50 -> 0 | H37: =SUM(E37:G37) -> 0
C38: (-) Debit Notes | D38: 0 | E38: 0 | F38: 0 | G38: 0 | H38: =SUM(E38:G38) -> 0
C39: (-) ITC Reversed on Ineligible credit | D39: 0 | E39: 0 | F39: 0 | G39: 0 | H39: =SUM(E39:G39) -> 0
C41: (B) Total ITC Available for Set off | D41: =SUM(D33:D37)-SUM(D38:D39) -> 0 | E41: =SUM(E33:E37)-SUM(E38:E39) -> 0 | F41: =SUM(F33:F37)-SUM(F38:F39) -> 0 | G41: =SUM(G33:G37)-SUM(G38:G39) -> 0 | H41: =SUM(H33:H37)-SUM(H38:H39) -> 0
B43: Tax Set-off | C43: (A-B) Payable | E43: =E22-E41 -> 0 | F43: =F22-F41 -> 0 | G43: =G22-G41 -> 0 | H43: =H22-H41 -> 0
C44: (-) Adjustment | E44: 0 | F44: 0 | G44: 0 | H44: =SUM(E44:G44) -> 0
C46: (-) GST TDS/TCS Opening Cash Balance | E46: 0 | F46: 0 | G46: 0 | H46: =SUM(D46:G46) -> 0
C48: Final Liability Payable | E48: =IF(E43-E44>0,E43-E44,0)-E46 -> 0 | F48: =IF(F43-F44>0,F43-F44,0)-F46 -> 0 | G48: =IF(G43-G44>0,G43-G44,0)-G46 -> 0 | H48: =IF(H43-H44>0,H43-H44,0)-H46 -> 0
C50: Balance C/f to next month | E50: =IF(E43-E44<0,E44-E43,0) -> 0 | F50: =IF(F43-F44<0,F44-F43,0) -> 0 | G50: =IF(G43-G44<0,G44-G43,0) -> 0 | H50: =SUM(E50:G50) -> 0
...

Sheet January-2027
G1: January
B2: DYP INFRAPROJECTS PRIVATE LIMITED
B3: GST No. 27AAGCD4105L1ZO
B5: GSTR-3B WORKING FOR THE MONTH OF JANUARY 2027
B6: PARTICULARS | D6: TAXABLE | E6: CGST | F6: SGST | G6: IGST | H6: TOTAL
B8: Outward Supply | C8: Sales (B2B) | D8: 0 | E8: 0 | F8: 0 | G8: 0 | H8: =SUM(E8:G8) -> 0
C9: Sales (B2C) | D9: 0 | E9: 0 | F9: 0 | G9: 0 | H9: =SUM(E9:G9) -> 0
C10: SEZ supply with payment | D10: 0 | E10: 0 | F10: 0 | G10: 0 | H10: =SUM(E10:G10) -> 0
C11: SEZ supply without-payment | D11: 0 | E11: 0 | F11: 0 | G11: 0 | H11: =SUM(E11:G11) -> 0
C12: Zero Rated Supply/Export Sale | D12: 0 | E12: 0 | F12: 0 | G12: 0 | H12: =SUM(E12:G12) -> 0
C13: Nil Rated Supply | D13: 0 | E13: 0 | F13: 0 | G13: 0 | H13: =SUM(E13:G13) -> 0
C14: Exempt Sale | D14: 0 | E14: 0 | F14: 0 | G14: 0 | H14: =SUM(E14:G14) -> 0
C15: Advances Collected for Services | D15: 0 | E15: 0 | F15: 0 | G15: 0 | H15: =SUM(E15:G15) -> 0
C16: Rent Received | D16: 0 | E16: 0 | F16: 0 | G16: 0 | H16: =SUM(E16:G16) -> 0
C17: Sale Increased through Amendment | D17: 0 | E17: 0 | F17: 0 | G17: 0 | H17: =SUM(E17:G17) -> 0
C18: (-) Sale Decreased through Amendment | D18: 0 | E18: 0 | F18: 0 | G18: 0 | H18: =SUM(E18:G18) -> 0
C19: (-) Credit Note | D19: 0 | E19: 0 | F19: 0 | G19: 0 | H19: =SUM(E19:G19) -> 0
C20: (-) Advances Settled Against Services | D20: 0 | E20: 0 | F20: 0 | G20: 0 | H20: =SUM(E20:G20) -> 0
C22: Total Sale as per Working | D22: =SUM(D8:D17)-SUM(D18:D20) -> 0 | E22: =SUM(E8:E17)-SUM(E18:E20) -> 0 | F22: =SUM(F8:F17)-SUM(F18:F20) -> 0 | G22: =SUM(G8:G17)-SUM(G18:G20) -> 0 | H22: =SUM(H8:H17)-SUM(H18:H20) -> 0
C24: Reverse Charge on Inward Supplies | D24: =SUM(D25:D28) -> 0 | E24: =SUM(E25:E28) -> 0 | F24: =SUM(F25:F28) -> 0 | G24: =SUM(G25:G28) -> 0 | H24: =SUM(H25:H28) -> 0
C25: RCM on Transport Charges 5% | D25: 0 | E25: 0 | F25: 0 | G25: 0 | H25: =SUM(E25:G25) -> 0
C26: RCM on Security Charges 18% | D26: 0 | E26: 0 | F26: 0 | G26: 0 | H26: =SUM(E26:G26) -> 0
C27: RCM on Guest House Charges 18% | D27: 0 | E27: 0 | F27: 0 | G27: 0 | H27: =SUM(E27:G27) -> 0
C28: RCM on Advocate Charges 18% | D28: 0 | E28: 0 | F28: 0 | G28: 0 | H28: =SUM(E28:G28) -> 0
C30: (A) Total Sale as per Working including Reverse Charge | D30: =SUM(D22:D24) -> 0 | E30: =SUM(E22:E24) -> 0 | F30: =SUM(F22:F24) -> 0 | G30: =SUM(G22:G24) -> 0 | H30: =SUM(H22:H24) -> 0
B31: Inward Supplies
C32: ITC (As per books) | H32: 0
C33: ITC as per GSTR 2B | D33: 0 | E33: 0 | F33: 0 | G33: 0 | H33: =SUM(E33:G33) -> 0
C34: (+) Import purchase | D34: 0 | E34: 0 | F34: 0 | G34: 0 | H34: =SUM(E34:G34) -> 0
C35: (+) RCM paid on Inward Supplies | D35: =D24 -> 0 | E35: =E24 -> 0 | F35: =F24 -> 0 | G35: =G24 -> 0 | H35: =SUM(E35:G35) -> 0
C36: (+) Credit Notes | D36: 0 | E36: 0 | F36: 0 | G36: 0 | H36: =SUM(E36:G36) -> 0
C37: (+) Opening Credit Balance | D37: 0 | E37: ='December-2026'!E50 -> 0 | F37: ='December-2026'!F50 -> 0 | G37: ='December-2026'!G50 -> 0 | H37: =SUM(E37:G37) -> 0
C38: (-) Debit Notes | D38: 0 | E38: 0 | F38: 0 | G38: 0 | H38: =SUM(E38:G38) -> 0
C39: (-) ITC Reversed on Ineligible credit | D39: 0 | E39: 0 | F39: 0 | G39: 0 | H39: =SUM(E39:G39) -> 0
C41: (B) Total ITC Available for Set off | D41: =SUM(D33:D37)-SUM(D38:D39) -> 0 | E41: =SUM(E33:E37)-SUM(E38:E39) -> 0 | F41: =SUM(F33:F37)-SUM(F38:F39) -> 0 | G41: =SUM(G33:G37)-SUM(G38:G39) -> 0 | H41: =SUM(H33:H37)-SUM(H38:H39) -> 0
B43: Tax Set-off | C43: (A-B) Payable | E43: =E22-E41 -> 0 | F43: =F22-F41 -> 0 | G43: =G22-G41 -> 0 | H43: =H22-H41 -> 0
C44: (-) Adjustment | E44: 0 | F44: 0 | G44: 0 | H44: =SUM(E44:G44) -> 0
C46: (-) GST TDS/TCS Opening Cash Balance | E46: 0 | F46: 0 | G46: 0 | H46: =SUM(D46:G46) -> 0
C48: Final Liability Payable | E48: =IF(E43-E44>0,E43-E44,0)-E46 -> 0 | F48: =IF(F43-F44>0,F43-F44,0)-F46 -> 0 | G48: =IF(G43-G44>0,G43-G44,0)-G46 -> 0 | H48: =IF(H43-H44>0,H43-H44,0)-H46 -> 0
C50: Balance C/f to next month | E50: =IF(E43-E44<0,E44-E43,0) -> 0 | F50: =IF(F43-F44<0,F44-F43,0) -> 0 | G50: =IF(G43-G44<0,G44-G43,0) -> 0 | H50: =SUM(E50:G50) -> 0
...

Sheet February-2027
G1: February
B2: DYP INFRAPROJECTS PRIVATE LIMITED
B3: GST No. 27AAGCD4105L1ZO
B5: GSTR-3B WORKING FOR THE MONTH OF FEBRUARY 2027
B6: PARTICULARS | D6: TAXABLE | E6: CGST | F6: SGST | G6: IGST | H6: TOTAL
B8: Outward Supply | C8: Sales (B2B) | D8: 0 | E8: 0 | F8: 0 | G8: 0 | H8: =SUM(E8:G8) -> 0
C9: Sales (B2C) | D9: 0 | E9: 0 | F9: 0 | G9: 0 | H9: =SUM(E9:G9) -> 0
C10: SEZ supply with payment | D10: 0 | E10: 0 | F10: 0 | G10: 0 | H10: =SUM(E10:G10) -> 0
C11: SEZ supply without-payment | D11: 0 | E11: 0 | F11: 0 | G11: 0 | H11: =SUM(E11:G11) -> 0
C12: Zero Rated Supply/Export Sale | D12: 0 | E12: 0 | F12: 0 | G12: 0 | H12: =SUM(E12:G12) -> 0
C13: Nil Rated Supply | D13: 0 | E13: 0 | F13: 0 | G13: 0 | H13: =SUM(E13:G13) -> 0
C14: Exempt Sale | D14: 0 | E14: 0 | F14: 0 | G14: 0 | H14: =SUM(E14:G14) -> 0
C15: Advances Collected for Services | D15: 0 | E15: 0 | F15: 0 | G15: 0 | H15: =SUM(E15:G15) -> 0
C16: Rent Received | D16: 0 | E16: 0 | F16: 0 | G16: 0 | H16: =SUM(E16:G16) -> 0
C17: Sale Increased through Amendment | D17: 0 | E17: 0 | F17: 0 | G17: 0 | H17: =SUM(E17:G17) -> 0
C18: (-) Sale Decreased through Amendment | D18: 0 | E18: 0 | F18: 0 | G18: 0 | H18: =SUM(E18:G18) -> 0
C19: (-) Credit Note | D19: 0 | E19: 0 | F19: 0 | G19: 0 | H19: =SUM(E19:G19) -> 0
C20: (-) Advances Settled Against Services | D20: 0 | E20: 0 | F20: 0 | G20: 0 | H20: =SUM(E20:G20) -> 0
C22: Total Sale as per Working | D22: =SUM(D8:D17)-SUM(D18:D20) -> 0 | E22: =SUM(E8:E17)-SUM(E18:E20) -> 0 | F22: =SUM(F8:F17)-SUM(F18:F20) -> 0 | G22: =SUM(G8:G17)-SUM(G18:G20) -> 0 | H22: =SUM(H8:H17)-SUM(H18:H20) -> 0
C24: Reverse Charge on Inward Supplies | D24: =SUM(D25:D28) -> 0 | E24: =SUM(E25:E28) -> 0 | F24: =SUM(F25:F28) -> 0 | G24: =SUM(G25:G28) -> 0 | H24: =SUM(H25:H28) -> 0
C25: RCM on Transport Charges 5% | D25: 0 | E25: 0 | F25: 0 | G25: 0 | H25: =SUM(E25:G25) -> 0
C26: RCM on Security Charges 18% | D26: 0 | E26: 0 | F26: 0 | G26: 0 | H26: =SUM(E26:G26) -> 0
C27: RCM on Guest House Charges 18% | D27: 0 | E27: 0 | F27: 0 | G27: 0 | H27: =SUM(E27:G27) -> 0
C28: RCM on Advocate Charges 18% | D28: 0 | E28: 0 | F28: 0 | G28: 0 | H28: =SUM(E28:G28) -> 0
C30: (A) Total Sale as per Working including Reverse Charge | D30: =SUM(D22:D24) -> 0 | E30: =SUM(E22:E24) -> 0 | F30: =SUM(F22:F24) -> 0 | G30: =SUM(G22:G24) -> 0 | H30: =SUM(H22:H24) -> 0
B31: Inward Supplies
C32: ITC (As per books) | H32: 0
C33: ITC as per GSTR 2B | D33: 0 | E33: 0 | F33: 0 | G33: 0 | H33: =SUM(E33:G33) -> 0
C34: (+) Import purchase | D34: 0 | E34: 0 | F34: 0 | G34: 0 | H34: =SUM(E34:G34) -> 0
C35: (+) RCM paid on Inward Supplies | D35: =D24 -> 0 | E35: =E24 -> 0 | F35: =F24 -> 0 | G35: =G24 -> 0 | H35: =SUM(E35:G35) -> 0
C36: (+) Credit Notes | D36: 0 | E36: 0 | F36: 0 | G36: 0 | H36: =SUM(E36:G36) -> 0
C37: (+) Opening Credit Balance | D37: 0 | E37: ='January-2027'!E50 -> 0 | F37: ='January-2027'!F50 -> 0 | G37: ='January-2027'!G50 -> 0 | H37: =SUM(E37:G37) -> 0
C38: (-) Debit Notes | D38: 0 | E38: 0 | F38: 0 | G38: 0 | H38: =SUM(E38:G38) -> 0
C39: (-) ITC Reversed on Ineligible credit | D39: 0 | E39: 0 | F39: 0 | G39: 0 | H39: =SUM(E39:G39) -> 0
C41: (B) Total ITC Available for Set off | D41: =SUM(D33:D37)-SUM(D38:D39) -> 0 | E41: =SUM(E33:E37)-SUM(E38:E39) -> 0 | F41: =SUM(F33:F37)-SUM(F38:F39) -> 0 | G41: =SUM(G33:G37)-SUM(G38:G39) -> 0 | H41: =SUM(H33:H37)-SUM(H38:H39) -> 0
B43: Tax Set-off | C43: (A-B) Payable | E43: =E22-E41 -> 0 | F43: =F22-F41 -> 0 | G43: =G22-G41 -> 0 | H43: =H22-H41 -> 0
C44: (-) Adjustment | E44: 0 | F44: 0 | G44: 0 | H44: =SUM(E44:G44) -> 0
C46: (-) GST TDS/TCS Opening Cash Balance | E46: 0 | F46: 0 | G46: 0 | H46: =SUM(D46:G46) -> 0
C48: Final Liability Payable | E48: =IF(E43-E44>0,E43-E44,0)-E46 -> 0 | F48: =IF(F43-F44>0,F43-F44,0)-F46 -> 0 | G48: =IF(G43-G44>0,G43-G44,0)-G46 -> 0 | H48: =IF(H43-H44>0,H43-H44,0)-H46 -> 0
C50: Balance C/f to next month | E50: =IF(E43-E44<0,E44-E43,0) -> 0 | F50: =IF(F43-F44<0,F44-F43,0) -> 0 | G50: =IF(G43-G44<0,G44-G43,0) -> 0 | H50: =SUM(E50:G50) -> 0
...

Sheet March-2027
G1: March
B2: DYP INFRAPROJECTS PRIVATE LIMITED
B3: GST No. 27AAGCD4105L1ZO
B5: GSTR-3B WORKING FOR THE MONTH OF MARCH 2027
B6: PARTICULARS | D6: TAXABLE | E6: CGST | F6: SGST | G6: IGST | H6: TOTAL
B8: Outward Supply | C8: Sales (B2B) | D8: 0 | E8: 0 | F8: 0 | G8: 0 | H8: =SUM(E8:G8) -> 0
C9: Sales (B2C) | D9: 0 | E9: 0 | F9: 0 | G9: 0 | H9: =SUM(E9:G9) -> 0
C10: SEZ supply with payment | D10: 0 | E10: 0 | F10: 0 | G10: 0 | H10: =SUM(E10:G10) -> 0
C11: SEZ supply without-payment | D11: 0 | E11: 0 | F11: 0 | G11: 0 | H11: =SUM(E11:G11) -> 0
C12: Zero Rated Supply/Export Sale | D12: 0 | E12: 0 | F12: 0 | G12: 0 | H12: =SUM(E12:G12) -> 0
C13: Nil Rated Supply | D13: 0 | E13: 0 | F13: 0 | G13: 0 | H13: =SUM(E13:G13) -> 0
C14: Exempt Sale | D14: 0 | E14: 0 | F14: 0 | G14: 0 | H14: =SUM(E14:G14) -> 0
C15: Advances Collected for Services | D15: 0 | E15: 0 | F15: 0 | G15: 0 | H15: =SUM(E15:G15) -> 0
C16: Rent Received | D16: 0 | E16: 0 | F16: 0 | G16: 0 | H16: =SUM(E16:G16) -> 0
C17: Sale Increased through Amendment | D17: 0 | E17: 0 | F17: 0 | G17: 0 | H17: =SUM(E17:G17) -> 0
C18: (-) Sale Decreased through Amendment | D18: 0 | E18: 0 | F18: 0 | G18: 0 | H18: =SUM(E18:G18) -> 0
C19: (-) Credit Note | D19: 0 | E19: 0 | F19: 0 | G19: 0 | H19: =SUM(E19:G19) -> 0
C20: (-) Advances Settled Against Services | D20: 0 | E20: 0 | F20: 0 | G20: 0 | H20: =SUM(E20:G20) -> 0
C22: Total Sale as per Working | D22: =SUM(D8:D17)-SUM(D18:D20) -> 0 | E22: =SUM(E8:E17)-SUM(E18:E20) -> 0 | F22: =SUM(F8:F17)-SUM(F18:F20) -> 0 | G22: =SUM(G8:G17)-SUM(G18:G20) -> 0 | H22: =SUM(H8:H17)-SUM(H18:H20) -> 0
C24: Reverse Charge on Inward Supplies | D24: =SUM(D25:D28) -> 0 | E24: =SUM(E25:E28) -> 0 | F24: =SUM(F25:F28) -> 0 | G24: =SUM(G25:G28) -> 0 | H24: =SUM(H25:H28) -> 0
C25: RCM on Transport Charges 5% | D25: 0 | E25: 0 | F25: 0 | G25: 0 | H25: =SUM(E25:G25) -> 0
C26: RCM on Security Charges 18% | D26: 0 | E26: 0 | F26: 0 | G26: 0 | H26: =SUM(E26:G26) -> 0
C27: RCM on Guest House Charges 18% | D27: 0 | E27: 0 | F27: 0 | G27: 0 | H27: =SUM(E27:G27) -> 0
C28: RCM on Advocate Charges 18% | D28: 0 | E28: 0 | F28: 0 | G28: 0 | H28: =SUM(E28:G28) -> 0
C30: (A) Total Sale as per Working including Reverse Charge | D30: =SUM(D22:D24) -> 0 | E30: =SUM(E22:E24) -> 0 | F30: =SUM(F22:F24) -> 0 | G30: =SUM(G22:G24) -> 0 | H30: =SUM(H22:H24) -> 0
B31: Inward Supplies
C32: ITC (As per books) | H32: 0
C33: ITC as per GSTR 2B | D33: 0 | E33: 0 | F33: 0 | G33: 0 | H33: =SUM(E33:G33) -> 0
C34: (+) Import purchase | D34: 0 | E34: 0 | F34: 0 | G34: 0 | H34: =SUM(E34:G34) -> 0
C35: (+) RCM paid on Inward Supplies | D35: =D24 -> 0 | E35: =E24 -> 0 | F35: =F24 -> 0 | G35: =G24 -> 0 | H35: =SUM(E35:G35) -> 0
C36: (+) Credit Notes | D36: 0 | E36: 0 | F36: 0 | G36: 0 | H36: =SUM(E36:G36) -> 0
C37: (+) Opening Credit Balance | D37: 0 | E37: ='February-2027'!E50 -> 0 | F37: ='February-2027'!F50 -> 0 | G37: ='February-2027'!G50 -> 0 | H37: =SUM(E37:G37) -> 0
C38: (-) Debit Notes | D38: 0 | E38: 0 | F38: 0 | G38: 0 | H38: =SUM(E38:G38) -> 0
C39: (-) ITC Reversed on Ineligible credit | D39: 0 | E39: 0 | F39: 0 | G39: 0 | H39: =SUM(E39:G39) -> 0
C41: (B) Total ITC Available for Set off | D41: =SUM(D33:D37)-SUM(D38:D39) -> 0 | E41: =SUM(E33:E37)-SUM(E38:E39) -> 0 | F41: =SUM(F33:F37)-SUM(F38:F39) -> 0 | G41: =SUM(G33:G37)-SUM(G38:G39) -> 0 | H41: =SUM(H33:H37)-SUM(H38:H39) -> 0
B43: Tax Set-off | C43: (A-B) Payable | E43: =E22-E41 -> 0 | F43: =F22-F41 -> 0 | G43: =G22-G41 -> 0 | H43: =H22-H41 -> 0
C44: (-) Adjustment | E44: 0 | F44: 0 | G44: 0 | H44: =SUM(E44:G44) -> 0
C46: (-) GST TDS/TCS Opening Cash Balance | E46: 0 | F46: 0 | G46: 0 | H46: =SUM(D46:G46) -> 0
C48: Final Liability Payable | E48: =IF(E43-E44>0,E43-E44,0)-E46 -> 0 | F48: =IF(F43-F44>0,F43-F44,0)-F46 -> 0 | G48: =IF(G43-G44>0,G43-G44,0)-G46 -> 0 | H48: =IF(H43-H44>0,H43-H44,0)-H46 -> 0
C50: Balance C/f to next month | E50: =IF(E43-E44<0,E44-E43,0) -> 0 | F50: =IF(F43-F44<0,F44-F43,0) -> 0 | G50: =IF(G43-G44<0,G44-G43,0) -> 0 | H50: =SUM(E50:G50) -> 0
...

Sheet Consolidated Sheet 2026-27
G1: Consolidated
B2: DYP INFRAPROJECTS PRIVATE LIMITED
B3: GST No. 27AAGCD4105L1ZO
B5: GSTR-3B WORKING CONSOLIDATED SHEET 2026-27
B6: PARTICULARS | D6: TAXABLE | E6: CGST | F6: SGST | G6: IGST | H6: TOTAL
B8: Outward Supply | C8: Sales (B2B) | D8: ='April-2026'!D8+'May-2026'!D8+'June-2026'!D8+'July-2026'!D8+'August-2026'!D8+'September-2026'!D8+'October-2026'!D8+'November-2026'!D8+'December-2026'!D8+'January-2027'!D8+'February-2027'!D8+'March-2027'!D8 | E8: ='April-2026'!E8+'May-2026'!E8+'June-2026'!E8+'July-2026'!E8+'August-2026'!E8+'September-2026'!E8+'October-2026'!E8+'November-2026'!E8+'December-2026'!E8+'January-2027'!E8+'February-2027'!E8+'March-2027'!E8 | F8: ='April-2026'!F8+'May-2026'!F8+'June-2026'!F8+'July-2026'!F8+'August-2026'!F8+'September-2026'!F8+'October-2026'!F8+'November-2026'!F8+'December-2026'!F8+'January-2027'!F8+'February-2027'!F8+'March-2027'!F8 | G8: ='April-2026'!G8+'May-2026'!G8+'June-2026'!G8+'July-2026'!G8+'August-2026'!G8+'September-2026'!G8+'October-2026'!G8+'November-2026'!G8+'December-2026'!G8+'January-2027'!G8+'February-2027'!G8+'March-2027'!G8 | H8: =SUM(E8:G8)
C9: Sales (B2C) | D9: ='April-2026'!D9+'May-2026'!D9+'June-2026'!D9+'July-2026'!D9+'August-2026'!D9+'September-2026'!D9+'October-2026'!D9+'November-2026'!D9+'December-2026'!D9+'January-2027'!D9+'February-2027'!D9+'March-2027'!D9 | E9: ='April-2026'!E9+'May-2026'!E9+'June-2026'!E9+'July-2026'!E9+'August-2026'!E9+'September-2026'!E9+'October-2026'!E9+'November-2026'!E9+'December-2026'!E9+'January-2027'!E9+'February-2027'!E9+'March-2027'!E9 | F9: ='April-2026'!F9+'May-2026'!F9+'June-2026'!F9+'July-2026'!F9+'August-2026'!F9+'September-2026'!F9+'October-2026'!F9+'November-2026'!F9+'December-2026'!F9+'January-2027'!F9+'February-2027'!F9+'March-2027'!F9 | G9: ='April-2026'!G9+'May-2026'!G9+'June-2026'!G9+'July-2026'!G9+'August-2026'!G9+'September-2026'!G9+'October-2026'!G9+'November-2026'!G9+'December-2026'!G9+'January-2027'!G9+'February-2027'!G9+'March-2027'!G9 | H9: =SUM(E9:G9)
C10: SEZ supply with payment | D10: ='April-2026'!D10+'May-2026'!D10+'June-2026'!D10+'July-2026'!D10+'August-2026'!D10+'September-2026'!D10+'October-2026'!D10+'November-2026'!D10+'December-2026'!D10+'January-2027'!D10+'February-2027'!D10+'March-2027'!D10 | E10: ='April-2026'!E10+'May-2026'!E10+'June-2026'!E10+'July-2026'!E10+'August-2026'!E10+'September-2026'!E10+'October-2026'!E10+'November-2026'!E10+'December-2026'!E10+'January-2027'!E10+'February-2027'!E10+'March-2027'!E10 | F10: ='April-2026'!F10+'May-2026'!F10+'June-2026'!F10+'July-2026'!F10+'August-2026'!F10+'September-2026'!F10+'October-2026'!F10+'November-2026'!F10+'December-2026'!F10+'January-2027'!F10+'February-2027'!F10+'March-2027'!F10 | G10: ='April-2026'!G10+'May-2026'!G10+'June-2026'!G10+'July-2026'!G10+'August-2026'!G10+'September-2026'!G10+'October-2026'!G10+'November-2026'!G10+'December-2026'!G10+'January-2027'!G10+'February-2027'!G10+'March-2027'!G10 | H10: =SUM(E10:G10)
C11: SEZ supply without-payment | D11: ='April-2026'!D11+'May-2026'!D11+'June-2026'!D11+'July-2026'!D11+'August-2026'!D11+'September-2026'!D11+'October-2026'!D11+'November-2026'!D11+'December-2026'!D11+'January-2027'!D11+'February-2027'!D11+'March-2027'!D11 | E11: ='April-2026'!E11+'May-2026'!E11+'June-2026'!E11+'July-2026'!E11+'August-2026'!E11+'September-2026'!E11+'October-2026'!E11+'November-2026'!E11+'December-2026'!E11+'January-2027'!E11+'February-2027'!E11+'March-2027'!E11 | F11: ='April-2026'!F11+'May-2026'!F11+'June-2026'!F11+'July-2026'!F11+'August-2026'!F11+'September-2026'!F11+'October-2026'!F11+'November-2026'!F11+'December-2026'!F11+'January-2027'!F11+'February-2027'!F11+'March-2027'!F11 | G11: ='April-2026'!G11+'May-2026'!G11+'June-2026'!G11+'July-2026'!G11+'August-2026'!G11+'September-2026'!G11+'October-2026'!G11+'November-2026'!G11+'December-2026'!G11+'January-2027'!G11+'February-2027'!G11+'March-2027'!G11 | H11: =SUM(E11:G11)
C12: Zero Rated Supply/Export Sale | D12: ='April-2026'!D12+'May-2026'!D12+'June-2026'!D12+'July-2026'!D12+'August-2026'!D12+'September-2026'!D12+'October-2026'!D12+'November-2026'!D12+'December-2026'!D12+'January-2027'!D12+'February-2027'!D12+'March-2027'!D12 | E12: ='April-2026'!E12+'May-2026'!E12+'June-2026'!E12+'July-2026'!E12+'August-2026'!E12+'September-2026'!E12+'October-2026'!E12+'November-2026'!E12+'December-2026'!E12+'January-2027'!E12+'February-2027'!E12+'March-2027'!E12 | F12: ='April-2026'!F12+'May-2026'!F12+'June-2026'!F12+'July-2026'!F12+'August-2026'!F12+'September-2026'!F12+'October-2026'!F12+'November-2026'!F12+'December-2026'!F12+'January-2027'!F12+'February-2027'!F12+'March-2027'!F12 | G12: ='April-2026'!G12+'May-2026'!G12+'June-2026'!G12+'July-2026'!G12+'August-2026'!G12+'September-2026'!G12+'October-2026'!G12+'November-2026'!G12+'December-2026'!G12+'January-2027'!G12+'February-2027'!G12+'March-2027'!G12 | H12: =SUM(E12:G12)
C13: Nil Rated Supply | D13: ='April-2026'!D13+'May-2026'!D13+'June-2026'!D13+'July-2026'!D13+'August-2026'!D13+'September-2026'!D13+'October-2026'!D13+'November-2026'!D13+'December-2026'!D13+'January-2027'!D13+'February-2027'!D13+'March-2027'!D13 | E13: ='April-2026'!E13+'May-2026'!E13+'June-2026'!E13+'July-2026'!E13+'August-2026'!E13+'September-2026'!E13+'October-2026'!E13+'November-2026'!E13+'December-2026'!E13+'January-2027'!E13+'February-2027'!E13+'March-2027'!E13 | F13: ='April-2026'!F13+'May-2026'!F13+'June-2026'!F13+'July-2026'!F13+'August-2026'!F13+'September-2026'!F13+'October-2026'!F13+'November-2026'!F13+'December-2026'!F13+'January-2027'!F13+'February-2027'!F13+'March-2027'!F13 | G13: ='April-2026'!G13+'May-2026'!G13+'June-2026'!G13+'July-2026'!G13+'August-2026'!G13+'September-2026'!G13+'October-2026'!G13+'November-2026'!G13+'December-2026'!G13+'January-2027'!G13+'February-2027'!G13+'March-2027'!G13 | H13: =SUM(E13:G13)
C14: Exempt Sale | D14: ='April-2026'!D14+'May-2026'!D14+'June-2026'!D14+'July-2026'!D14+'August-2026'!D14+'September-2026'!D14+'October-2026'!D14+'November-2026'!D14+'December-2026'!D14+'January-2027'!D14+'February-2027'!D14+'March-2027'!D14 | E14: ='April-2026'!E14+'May-2026'!E14+'June-2026'!E14+'July-2026'!E14+'August-2026'!E14+'September-2026'!E14+'October-2026'!E14+'November-2026'!E14+'December-2026'!E14+'January-2027'!E14+'February-2027'!E14+'March-2027'!E14 | F14: ='April-2026'!F14+'May-2026'!F14+'June-2026'!F14+'July-2026'!F14+'August-2026'!F14+'September-2026'!F14+'October-2026'!F14+'November-2026'!F14+'December-2026'!F14+'January-2027'!F14+'February-2027'!F14+'March-2027'!F14 | G14: ='April-2026'!G14+'May-2026'!G14+'June-2026'!G14+'July-2026'!G14+'August-2026'!G14+'September-2026'!G14+'October-2026'!G14+'November-2026'!G14+'December-2026'!G14+'January-2027'!G14+'February-2027'!G14+'March-2027'!G14 | H14: =SUM(E14:G14)
C15: Advances Collected for Services | D15: ='April-2026'!D15+'May-2026'!D15+'June-2026'!D15+'July-2026'!D15+'August-2026'!D15+'September-2026'!D15+'October-2026'!D15+'November-2026'!D15+'December-2026'!D15+'January-2027'!D15+'February-2027'!D15+'March-2027'!D15 | E15: ='April-2026'!E15+'May-2026'!E15+'June-2026'!E15+'July-2026'!E15+'August-2026'!E15+'September-2026'!E15+'October-2026'!E15+'November-2026'!E15+'December-2026'!E15+'January-2027'!E15+'February-2027'!E15+'March-2027'!E15 | F15: ='April-2026'!F15+'May-2026'!F15+'June-2026'!F15+'July-2026'!F15+'August-2026'!F15+'September-2026'!F15+'October-2026'!F15+'November-2026'!F15+'December-2026'!F15+'January-2027'!F15+'February-2027'!F15+'March-2027'!F15 | G15: ='April-2026'!G15+'May-2026'!G15+'June-2026'!G15+'July-2026'!G15+'August-2026'!G15+'September-2026'!G15+'October-2026'!G15+'November-2026'!G15+'December-2026'!G15+'January-2027'!G15+'February-2027'!G15+'March-2027'!G15 | H15: =SUM(E15:G15)
C16: Rent Received | D16: ='April-2026'!D16+'May-2026'!D16+'June-2026'!D16+'July-2026'!D16+'August-2026'!D16+'September-2026'!D16+'October-2026'!D16+'November-2026'!D16+'December-2026'!D16+'January-2027'!D16+'February-2027'!D16+'March-2027'!D16 | E16: ='April-2026'!E16+'May-2026'!E16+'June-2026'!E16+'July-2026'!E16+'August-2026'!E16+'September-2026'!E16+'October-2026'!E16+'November-2026'!E16+'December-2026'!E16+'January-2027'!E16+'February-2027'!E16+'March-2027'!E16 | F16: ='April-2026'!F16+'May-2026'!F16+'June-2026'!F16+'July-2026'!F16+'August-2026'!F16+'September-2026'!F16+'October-2026'!F16+'November-2026'!F16+'December-2026'!F16+'January-2027'!F16+'February-2027'!F16+'March-2027'!F16 | G16: ='April-2026'!G16+'May-2026'!G16+'June-2026'!G16+'July-2026'!G16+'August-2026'!G16+'September-2026'!G16+'October-2026'!G16+'November-2026'!G16+'December-2026'!G16+'January-2027'!G16+'February-2027'!G16+'March-2027'!G16 | H16: =SUM(E16:G16)
C17: Sale Increased through Amendment | D17: ='April-2026'!D17+'May-2026'!D17+'June-2026'!D17+'July-2026'!D17+'August-2026'!D17+'September-2026'!D17+'October-2026'!D17+'November-2026'!D17+'December-2026'!D17+'January-2027'!D17+'February-2027'!D17+'March-2027'!D17 | E17: ='April-2026'!E17+'May-2026'!E17+'June-2026'!E17+'July-2026'!E17+'August-2026'!E17+'September-2026'!E17+'October-2026'!E17+'November-2026'!E17+'December-2026'!E17+'January-2027'!E17+'February-2027'!E17+'March-2027'!E17 | F17: ='April-2026'!F17+'May-2026'!F17+'June-2026'!F17+'July-2026'!F17+'August-2026'!F17+'September-2026'!F17+'October-2026'!F17+'November-2026'!F17+'December-2026'!F17+'January-2027'!F17+'February-2027'!F17+'March-2027'!F17 | G17: ='April-2026'!G17+'May-2026'!G17+'June-2026'!G17+'July-2026'!G17+'August-2026'!G17+'September-2026'!G17+'October-2026'!G17+'November-2026'!G17+'December-2026'!G17+'January-2027'!G17+'February-2027'!G17+'March-2027'!G17 | H17: =SUM(E17:G17)
C18: (-) Sale Decreased through Amendment | D18: ='April-2026'!D18+'May-2026'!D18+'June-2026'!D18+'July-2026'!D18+'August-2026'!D18+'September-2026'!D18+'October-2026'!D18+'November-2026'!D18+'December-2026'!D18+'January-2027'!D18+'February-2027'!D18+'March-2027'!D18 | E18: ='April-2026'!E18+'May-2026'!E18+'June-2026'!E18+'July-2026'!E18+'August-2026'!E18+'September-2026'!E18+'October-2026'!E18+'November-2026'!E18+'December-2026'!E18+'January-2027'!E18+'February-2027'!E18+'March-2027'!E18 | F18: ='April-2026'!F18+'May-2026'!F18+'June-2026'!F18+'July-2026'!F18+'August-2026'!F18+'September-2026'!F18+'October-2026'!F18+'November-2026'!F18+'December-2026'!F18+'January-2027'!F18+'February-2027'!F18+'March-2027'!F18 | G18: ='April-2026'!G18+'May-2026'!G18+'June-2026'!G18+'July-2026'!G18+'August-2026'!G18+'September-2026'!G18+'October-2026'!G18+'November-2026'!G18+'December-2026'!G18+'January-2027'!G18+'February-2027'!G18+'March-2027'!G18 | H18: =SUM(E18:G18)
